Workbook
Name solver_lhs2: Optimization!$B$57:$Q$57
Name solver_lhs17: Optimization!$B$41:$Q$56
Name solver_lhs14: Optimization!$B$41:$Q$56
Name solver_lhs6: Optimization!$B$41:$Q$56
Name TotalCost: Optimization!$C$58
Name solver_lhs4: Optimization!$M$52:$Q$56
Name solver_rhs5: Optimization!$S$41:$S$56
Name DistanceMatrix: Optimization!$B$23:$Q$38
Name solver_lhs8: Optimization!$B$41:$Q$56
Name solver_lhs9: Optimization!$B$41:$Q$56
Name solver_adj: Matrix!$A$40:$P$55
Name solver_opt: Optimization!$S$23
Name solver_lhs13: Optimization!$B$41:$Q$56
Name DecisionMatrix: Optimization!$B$41:$Q$56
Name solver_lhs5: Optimization!$R$41:$R$56
Name solver_lhs11: Optimization!$B$41:$Q$56
Name solver_lhs3: Optimization!$H$47:$L$51
Name solver_lhs16: Optimization!$B$41:$Q$56
Name solver_lhs1: Matrix!$A$40:$P$55
Name solver_lhs1: Optimization!$B$41:$G$46
Name solver_lhs7: Optimization!$B$41:$Q$56
Name solver_rhs2: Optimization!$B$58:$Q$58
Name solver_lhs15: Optimization!$B$41:$Q$56
Name solver_opt: Matrix!$B$57
Name solver_lhs10: Optimization!$B$41:$Q$56
Name solver_adj: Optimization!$B$41:$Q$56
Name solver_lhs12: Optimization!$B$41:$Q$56

Sheet Graph

Sheet Matrix
C3: Matrix with schools
C4: Schools | D4: FMU | E4: UNC Pembroke | F4: Chowan | G4: Ferrum | H4: Barton | I4: Mount Olive | J4: Belmont Abbey | K4: North Greenville | L4: Converse | M4: Lees-McRae | N4: King | O4: Young Harris | P4: Emmanuel | Q4: Southern Wesleyan | R4: Erskine | S4: Shorter
C5: FMU | D5: 0 | E5: 0 | F5: 0 | G5: 0 | H5: 0 | I5: 0 | J5: 131 | K5: 206 | L5: 182 | M5: 233 | N5: 330 | O5: 302 | P5: 255 | Q5: 211 | R5: 187 | S5: 375
C6: UNC Pembroke | D6: 0 | E6: 0 | F6: 0 | G6: 0 | H6: 0 | I6: 0 | J6: 131 | K6: 223 | L6: 190 | M6: 249 | N6: 307 | O6: 341 | P6: 295 | Q6: 253 | R6: 226 | S6: 414
C7: Chowan | D7: 0 | E7: 0 | F7: 0 | G7: 0 | H7: 0 | I7: 0 | J7: 272 | K7: 364 | L7: 331 | M7: 302 | N7: 355 | O7: 452 | P7: 428 | Q7: 386 | R7: 417 | S7: 561
C8: Ferrum | D8: 0 | E8: 0 | F8: 0 | G8: 0 | H8: 0 | I8: 0 | J8: 170 | K8: 244 | L8: 229 | M8: 161 | N8: 149 | O8: 338 | P8: 326 | Q8: 284 | R8: 298 | S8: 434
C9: Barton | D9: 0 | E9: 0 | F9: 0 | G9: 0 | H9: 0 | I9: 0 | J9: 222 | K9: 314 | L9: 280 | M9: 252 | N9: 305 | O9: 401 | P9: 377 | Q9: 335 | R9: 333 | S9: 511
C10: Mount Olive | D10: 0 | E10: 0 | F10: 0 | G10: 0 | H10: 0 | I10: 0 | J10: 233 | K10: 325 | L10: 292 | M10: 270 | N10: 324 | O10: 420 | P10: 379 | Q10: 336 | R10: 310 | S10: 497
C11: Belmont Abbey | D11: 131 | E11: 131 | F11: 272 | G11: 170 | H11: 222 | I11: 233 | J11: 0 | K11: 0 | L11: 0 | M11: 0 | N11: 0 | O11: 202 | P11: 154 | Q11: 114 | R11: 129 | S11: 290
C12: North Greenville | D12: 206 | E12: 223 | F12: 364 | G12: 244 | H12: 314 | I12: 325 | J12: 0 | K12: 0 | L12: 0 | M12: 0 | N12: 0 | O12: 113 | P12: 86.5 | Q12: 39.5 | R12: 61.9 | S12: 222
C13: Converse | D13: 182 | E13: 190 | F13: 331 | G13: 229 | H13: 280 | I13: 292 | J13: 0 | K13: 0 | L13: 0 | M13: 0 | N13: 0 | O13: 146 | P13: 98.3 | Q13: 58.3 | R13: 73.7 | S13: 234
C14: Lees-McRae | D14: 233 | E14: 249 | F14: 302 | G14: 161 | H14: 252 | I14: 270 | J14: 0 | K14: 0 | L14: 0 | M14: 0 | N14: 0 | O14: 184 | P14: 204 | Q14: 155 | R14: 177 | S14: 316
C15: King | D15: 330 | E15: 307 | F15: 355 | G15: 149 | H15: 305 | I15: 324 | J15: 0 | K15: 0 | L15: 0 | M15: 0 | N15: 0 | O15: 195 | P15: 217 | Q15: 167 | R15: 190 | S15: 288
C16: Young Harris | D16: 302 | E16: 341 | F16: 452 | G16: 338 | H16: 401 | I16: 420 | J16: 202 | K16: 113 | L16: 146 | M16: 184 | N16: 195 | O16: 0 | P16: 0 | Q16: 0 | R16: 0 | S16: 0
... C20: Shorter | D20: 375 | E20: 414 | F20: 561 | G20: 434 | H20: 511 | I20: 497 | J20: 290 | K20: 222 | L20: 234 | M20: 316 | N20: 288 | O20: 0 | P20: 0 | Q20: 0 | R20: 0 | S20: 0
B22: Matrix w/o schools | C22: 0 | D22: 0 | E22: 0 | F22: 0 | G22: 0 | H22: 0 | I22: 131 | J22: 206 | K22: 182 | L22: 233 | M22: 330 | N22: 302 | O22: 255 | P22: 211 | Q22: 187 | R22: 375
C23: 0 | D23: 0 | E23: 0 | F23: 0 | G23: 0 | H23: 0 | I23: 131 | J23: 223 | K23: 190 | L23: 249 | M23: 307 | N23: 341 | O23: 295 | P23: 253 | Q23: 226 | R23: 414
C24: 0 | D24: 0 | E24: 0 | F24: 0 | G24: 0 | H24: 0 | I24: 272 | J24: 364 | K24: 331 | L24: 302 | M24: 355 | N24: 452 | O24: 428 | P24: 386 | Q24: 417 | R24: 561
C25: 0 | D25: 0 | E25: 0 | F25: 0 | G25: 0 | H25: 0 | I25: 170 | J25: 244 | K25: 229 | L25: 161 | M25: 149 | N25: 338 | O25: 326 | P25: 284 | Q25: 298 | R25: 434
C26: 0 | D26: 0 | E26: 0 | F26: 0 | G26: 0 | H26: 0 | I26: 222 | J26: 314 | K26: 280 | L26: 252 | M26: 305 | N26: 401 | O26: 377 | P26: 335 | Q26: 333 | R26: 511
C27: 0 | D27: 0 | E27: 0 | F27: 0 | G27: 0 | H27: 0 | I27: 233 | J27: 325 | K27: 292 | L27: 270 | M27: 324 | N27: 420 | O27: 379 | P27: 336 | Q27: 310 | R27: 497
C28: 131 | D28: 131 | E28: 272 | F28: 170 | G28: 222 | H28: 233 | I28: 0 | J28: 0 | K28: 0 | L28: 0 | M28: 0 | N28: 202 | O28: 154 | P28: 114 | Q28: 129 | R28: 290
C29: 206 | D29: 223 | E29: 364 | F29: 244 | G29: 314 | H29: 325 | I29: 0 | J29: 0 | K29: 0 | L29: 0 | M29: 0 | N29: 113 | O29: 86.5 | P29: 39.5 | Q29: 61.9 | R29: 222
C30: 182 | D30: 190 | E30: 331 | F30: 229 | G30: 280 | H30: 292 | I30: 0 | J30: 0 | K30: 0 | L30: 0 | M30: 0 | N30: 146 | O30: 98.3 | P30: 58.3 | Q30: 73.7 | R30: 234
C31: 233 | D31: 249 | E31: 302 | F31: 161 | G31: 252 | H31: 270 | I31: 0 | J31: 0 | K31: 0 | L31: 0 | M31: 0 | N31: 184 | O31: 204 | P31: 155 | Q31: 177 | R31: 316
C32: 330 | D32: 307 | E32: 355 | F32: 149 | G32: 305 | H32: 324 | I32: 0 | J32: 0 | K32: 0 | L32: 0 | M32: 0 | N32: 195 | O32: 217 | P32: 167 | Q32: 190 | R32: 288
C33: 302 | D33: 341 | E33: 452 | F33: 338 | G33: 401 | H33: 420 | I33: 202 | J33: 113 | K33: 146 | L33: 184 | M33: 195 | N33: 0 | O33: 0 | P33: 0 | Q33: 0 | R33: 0
C34: 255 | D34: 295 | E34: 428 | F34: 326 | G34: 377 | H34: 379 | I34: 154 | J34: 86.5 | K34: 98.3 | L34: 204 | M34: 217 | N34: 0 | O34: 0 | P34: 0 | Q34: 0 | R34: 0
... C37: 375 | D37: 414 | E37: 561 | F37: 434 | G37: 511 | H37: 497 | I37: 290 | J37: 222 | K37: 234 | L37: 316 | M37: 288 | N37: 0 | O37: 0 | P37: 0 | Q37: 0 | R37: 0
A39: Decision Variable Matrix
A57: Total Cost = | B57: =SUMPRODUCT(DistanceMatrix,DecisionMatrix) -> 0

Sheet Optimization
A2: Schools | B2: FMU | C2: UNC Pembroke | D2: Chowan | E2: Ferrum | F2: Barton | G2: Mount Olive | H2: Belmont Abbey | I2: North Greenville | J2: Converse | K2: Lees-McRae | L2: King | M2: Young Harris | N2: Emmanuel | O2: Southern Wesleyan | P2: Erskine | Q2: Shorter
A3: FMU | B3: 0 | C3: 0 | D3: 0 | E3: 0 | F3: 0 | G3: 0 | H3: 131 | I3: 206 | J3: 182 | K3: 233 | L3: 330 | M3: 302 | N3: 255 | O3: 211 | P3: 187 | Q3: 375
A4: UNC Pembroke | B4: 0 | C4: 0 | D4: 0 | E4: 0 | F4: 0 | G4: 0 | H4: 131 | I4: 223 | J4: 190 | K4: 249 | L4: 307 | M4: 341 | N4: 295 | O4: 253 | P4: 226 | Q4: 414
A5: Chowan | B5: 0 | C5: 0 | D5: 0 | E5: 0 | F5: 0 | G5: 0 | H5: 272 | I5: 364 | J5: 331 | K5: 302 | L5: 355 | M5: 452 | N5: 428 | O5: 386 | P5: 417 | Q5: 561
A6: Ferrum | B6: 0 | C6: 0 | D6: 0 | E6: 0 | F6: 0 | G6: 0 | H6: 170 | I6: 244 | J6: 229 | K6: 161 | L6: 149 | M6: 338 | N6: 326 | O6: 284 | P6: 298 | Q6: 434
A7: Barton | B7: 0 | C7: 0 | D7: 0 | E7: 0 | F7: 0 | G7: 0 | H7: 222 | I7: 314 | J7: 280 | K7: 252 | L7: 305 | M7: 401 | N7: 377 | O7: 335 | P7: 333 | Q7: 511
A8: Mount Olive | B8: 0 | C8: 0 | D8: 0 | E8: 0 | F8: 0 | G8: 0 | H8: 233 | I8: 325 | J8: 292 | K8: 270 | L8: 324 | M8: 420 | N8: 379 | O8: 336 | P8: 310 | Q8: 497
A9: Belmont Abbey | B9: 131 | C9: 131 | D9: 272 | E9: 170 | F9: 222 | G9: 233 | H9: 0 | I9: 0 | J9: 0 | K9: 0 | L9: 0 | M9: 202 | N9: 154 | O9: 114 | P9: 129 | Q9: 290
A10: North Greenville | B10: 206 | C10: 223 | D10: 364 | E10: 244 | F10: 314 | G10: 325 | H10: 0 | I10: 0 | J10: 0 | K10: 0 | L10: 0 | M10: 113 | N10: 86.5 | O10: 39.5 | P10: 61.9 | Q10: 222
A11: Converse | B11: 182 | C11: 190 | D11: 331 | E11: 229 | F11: 280 | G11: 292 | H11: 0 | I11: 0 | J11: 0 | K11: 0 | L11: 0 | M11: 146 | N11: 98.3 | O11: 58.3 | P11: 73.7 | Q11: 234
A12: Lees-McRae | B12: 233 | C12: 249 | D12: 302 | E12: 161 | F12: 252 | G12: 270 | H12: 0 | I12: 0 | J12: 0 | K12: 0 | L12: 0 | M12: 184 | N12: 204 | O12: 155 | P12: 177 | Q12: 316
A13: King | B13: 330 | C13: 307 | D13: 355 | E13: 149 | F13: 305 | G13: 324 | H13: 0 | I13: 0 | J13: 0 | K13: 0 | L13: 0 | M13: 195 | N13: 217 | O13: 167 | P13: 190 | Q13: 288
A14: Young Harris | B14: 302 | C14: 341 | D14: 452 | E14: 338 | F14: 401 | G14: 420 | H14: 202 | I14: 113 | J14: 146 | K14: 184 | L14: 195 | M14: 0 | N14: 0 | O14: 0 | P14: 0 | Q14: 0
... A18: Shorter | B18: 375 | C18: 414 | D18: 561 | E18: 434 | F18: 511 | G18: 497 | H18: 290 | I18: 222 | J18: 234 | K18: 316 | L18: 288 | M18: 0 | N18: 0 | O18: 0 | P18: 0 | Q18: 0
B23: 0 | C23: 0 | D23: 0 | E23: 0 | F23: 0 | G23: 0 | H23: 131 | I23: 206 | J23: 182 | K23: 233 | L23: 330 | M23: 302 | N23: 255 | O23: 211 | P23: 187 | Q23: 375 | R23: Total mileage | S23: =SUMPRODUCT(DistanceMatrix,DecisionMatrix) -> 11255.2 | U23: set cost function
B24: 0 | C24: 0 | D24: 0 | E24: 0 | F24: 0 | G24: 0 | H24: 131 | I24: 223 | J24: 190 | K24: 249 | L24: 307 | M24: 341 | N24: 295 | O24: 253 | P24: 226 | Q24: 414 | S24: =COUNT($B$41:$Q$56) -> 256 | U24: I'll explain more in an email
B25: 0 | C25: 0 | D25: 0 | E25: 0 | F25: 0 | G25: 0 | H25: 272 | I25: 364 | J25: 331 | K25: 302 | L25: 355 | M25: 452 | N25: 428 | O25: 386 | P25: 417 | Q25: 561
B26: 0 | C26: 0 | D26: 0 | E26: 0 | F26: 0 | G26: 0 | H26: 170 | I26: 244 | J26: 229 | K26: 161 | L26: 149 | M26: 338 | N26: 326 | O26: 284 | P26: 298 | Q26: 434
B27: 0 | C27: 0 | D27: 0 | E27: 0 | F27: 0 | G27: 0 | H27: 222 | I27: 314 | J27: 280 | K27: 252 | L27: 305 | M27: 401 | N27: 377 | O27: 335 | P27: 333 | Q27: 511
B28: 0 | C28: 0 | D28: 0 | E28: 0 | F28: 0 | G28: 0 | H28: 233 | I28: 325 | J28: 292 | K28: 270 | L28: 324 | M28: 420 | N28: 379 | O28: 336 | P28: 310 | Q28: 497
B29: 131 | C29: 131 | D29: 272 | E29: 170 | F29: 222 | G29: 233 | H29: 0 | I29: 0 | J29: 0 | K29: 0 | L29: 0 | M29: 202 | N29: 154 | O29: 114 | P29: 129 | Q29: 290
B30: 206 | C30: 223 | D30: 364 | E30: 244 | F30: 314 | G30: 325 | H30: 0 | I30: 0 | J30: 0 | K30: 0 | L30: 0 | M30: 113 | N30: 86.5 | O30: 39.5 | P30: 61.9 | Q30: 222
B31: 182 | C31: 190 | D31: 331 | E31: 229 | F31: 280 | G31: 292 | H31: 0 | I31: 0 | J31: 0 | K31: 0 | L31: 0 | M31: 146 | N31: 98.3 | O31: 58.3 | P31: 73.7 | Q31: 234
B32: 233 | C32: 249 | D32: 302 | E32: 161 | F32: 252 | G32: 270 | H32: 0 | I32: 0 | J32: 0 | K32: 0 | L32: 0 | M32: 184 | N32: 204 | O32: 155 | P32: 177 | Q32: 316
B33: 330 | C33: 307 | D33: 355 | E33: 149 | F33: 305 | G33: 324 | H33: 0 | I33: 0 | J33: 0 | K33: 0 | L33: 0 | M33: 195 | N33: 217 | O33: 167 | P33: 190 | Q33: 288
B34: 302 | C34: 341 | D34: 452 | E34: 338 | F34: 401 | G34: 420 | H34: 202 | I34: 113 | J34: 146 | K34: 184 | L34: 195 | M34: 0 | N34: 0 | O34: 0 | P34: 0 | Q34: 0
B35: 255 | C35: 295 | D35: 428 | E35: 326 | F35: 377 | G35: 379 | H35: 154 | I35: 86.5 | J35: 98.3 | K35: 204 | L35: 217 | M35: 0 | N35: 0 | O35: 0 | P35: 0 | Q35: 0
B36: 211 | C36: 253 | D36: 386 | E36: 284 | F36: 335 | G36: 336 | H36: 114 | I36: 39.5 | J36: 58.3 | K36: 155 | L36: 167 | M36: 0 | N36: 0 | O36: 0 | P36: 0 | Q36: 0
... B38: 375 | C38: 414 | D38: 561 | E38: 434 | F38: 511 | G38: 497 | H38: 290 | I38: 222 | J38: 234 | K38: 316 | L38: 288 | M38: 0 | N38: 0 | O38: 0 | P38: 0 | Q38: 0
B40: Decision Variable Matrix | U40: New Constraints
B41: 0 | C41: 0 | D41: 0 | E41: 0 | F41: 0 | G41: 0 | H41: 0 | I41: 0 | J41: 0 | K41: 0 | L41: 0 | M41: 0 | N41: 0 | O41: 1 | P41: 1 | Q41: 1 | R41: =SUM(B41:Q41) -> 3 | S41: 3 | U41: Set all inconference games variables =0
B42: 0 | C42: 0 | D42: 0 | E42: 0 | F42: 0 | G42: 0 | H42: 1 | I42: 0 | J42: 0 | K42: 0 | L42: 0 | M42: 0 | N42: 0 | O42: 0 | P42: 1 | Q42: 1 | R42: =SUM(B42:Q42) -> 3 | S42: 3 | U42: we'll add in the solver window
B43: 0 | C43: 0 | D43: 0 | E43: 0 | F43: 0 | G43: 0 | H43: 1 | I43: 0 | J43: 0 | K43: 1 | L43: 1 | M43: 0 | N43: 0 | O43: 0 | P43: 0 | Q43: 0 | R43: =SUM(B43:Q43) -> 3 | S43: 3
B44: 0 | C44: 0 | D44: 0 | E44: 0 | F44: 0 | G44: 0 | H44: 0 | I44: 0 | J44: 0 | K44: 1 | L44: 1 | M44: 1 | N44: 0 | O44: 0 | P44: 0 | Q44: 0 | R44: =SUM(B44:Q44) -> 3 | S44: 3
B45: 0 | C45: 0 | D45: 0 | E45: 0 | F45: 0 | G45: 0 | H45: 1 | I45: 0 | J45: 0 | K45: 1 | L45: 1 | M45: 0 | N45: 0 | O45: 0 | P45: 0 | Q45: 0 | R45: =SUM(B45:Q45) -> 3 | S45: 3
B46: 0 | C46: 0 | D46: 0 | E46: 0 | F46: 0 | G46: 0 | H46: 0 | I46: 0 | J46: 0 | K46: 0 | L46: 0 | M46: 0 | N46: 1 | O46: 0 | P46: 1 | Q46: 1 | R46: =SUM(B46:Q46) -> 3 | S46: 3
B47: 0 | C47: 1 | D47: 1 | E47: 0 | F47: 1 | G47: 0 | H47: 0 | I47: 0 | J47: 0 | K47: 0 | L47: 0 | M47: 0 | N47: 0 | O47: 0 | P47: 0 | Q47: 0 | R47: =SUM(B47:Q47) -> 3 | S47: 3
B48: 0 | C48: 0 | D48: 0 | E48: 0 | F48: 0 | G48: 0 | H48: 0 | I48: 0 | J48: 0 | K48: 0 | L48: 0 | M48: 1 | N48: 1 | O48: 1 | P48: 0 | Q48: 0 | R48: =SUM(B48:Q48) -> 3 | S48: 3
B49: 0 | C49: 0 | D49: 0 | E49: 0 | F49: 0 | G49: 0 | H49: 0 | I49: 0 | J49: 0 | K49: 0 | L49: 0 | M49: 1 | N49: 1 | O49: 1 | P49: 0 | Q49: 0 | R49: =SUM(B49:Q49) -> 3 | S49: 3
B50: 0 | C50: 0 | D50: 1 | E50: 1 | F50: 1 | G50: 0 | H50: 0 | I50: 0 | J50: 0 | K50: 0 | L50: 0 | M50: 0 | N50: 0 | O50: 0 | P50: 0 | Q50: 0 | R50: =SUM(B50:Q50) -> 3 | S50: 3
...

Sheet soccer cc games
A1: Game # | B1: Home | C1: Away | D1: Location | E1: City/State | F1: Day | G1: Day of Week | H1: Time | I1: Distance miles
A2: {=SEQUENCE(13,1)} -> 1 | B2: FMU | C2: Chowan Univ. | D2: Smith Univ. Center | E2: Florence, SC | F2: Sept. 13th | G2: Saturday | H2: 0.6875 | I2: 243
A3: 2 | B3: Univ. of Mount Olive | C3: FMU | D3: Kornegay Arena | E3: Mount Olive, NC | F3: Sept. 17th | G3: Wednesday | H3: 0.66666667 | I3: 136
A4: 3 | B4: Ferrum College | C4: FMU | D4: Swartz Gymnasium | E4: Ferrum, VA | F4: Sept. 20th | G4: Saturday | H4: 0.60416667 | I4: 228
A5: 4 | B5: FMU | C5: Converse Univ. | D5: Smith Univ. Center | E5: Florence, SC | F5: Sept. 27th | G5: Saturday | H5: 0.6875 | I5: 182
A6: 5 | B6: Barton College | C6: FMU | D6: Wilson Gymnasium | E6: Wilson, NC | F6: Oct. 1st | G6: Wednesday | H6: 0.66666667 | I6: 160
A7: 6 | B7: FMU | C7: Young Harris College | D7: Smith Univ. Center | E7: Florence, SC | F7: Oct. 4th | G7: Saturday | H7: 0.54166667 | I7: 302
A8: 7 | B8: UNC Pembroke | C8: FMU | D8: English E. Jones Center | E8: Pembroke, NC | F8: Oct. 7th | G8: Tuesday | H8: 0.70833333 | I8: 52.6
A9: 8 | B9: FMU | C9: Barton College | D9: Smith Univ. Center | E9: Florence, SC | F9: Oct. 15th | G9: Wednesday | H9: 0.6875 | I9: 160
A10: 9 | B10: FMU | C10: Ferrum College | D10: Smith Univ. Center | E10: Florence, SC | F10: Oct. 18th | G10: Saturday | H10: 0.66666667 | I10: 228
A11: 10 | B11: FMU | C11: Univ. of Mount Olive | D11: Smith Univ. Center | E11: Florence, SC | F11: Oct. 22nd | G11: Wednesday | H11: 0.6875 | I11: 136
A12: 11 | B12: Erskine College | C12: FMU | D12: Belk Arena | E12: Due West, SC | F12: Oct. 25th | G12: Saturday | H12: 0.54166667 | I12: 187
A13: 12 | B13: FMU | C13: UNC Pembroke | D13: Smith Univ. Center | E13: Florence, SC | F13: Oct. 28th | G13: Tuesday | H13: 0.70833333 | I13: 52.6
A14: 13 | B14: Chowan Univ. | C14: FMU | D14: Hawks Athletic Center | E14: Murfreesboro, NC | F14: Nov. 1st | G14: Saturday | H14: 0.6875 | I14: 243

Sheet __OpenSolverCache__

Sheet __OpenSolver__
A1: =ModelSheet=#REF! -> #NAME?
A2: =OpenSolver_AdjNum=0 -> #NAME?
A3: =OpenSolver_ChosenSolver=GLPK -> #NAME?
A4: =OpenSolver_FastBuild=0 -> #NAME?
A5: =OpenSolver_LinearityCheck=1 -> #NAME?
A6: =solver_neg=1 -> #NAME?
A7: =solver_num=0 -> #NAME?
A8: =solver_sho=1 -> #NAME?
A9: =solver_typ=2 -> #NAME?
A10: =solver_val=0 -> #NAME?

Sheet __OpenSolverCache__ (1)

Sheet __OpenSolver__ (1)
A1: =ModelSheet=#REF! -> #NAME? | B1: =ModelSheet=Optimization!A:Z -> #NAME?
A2: =OpenSolver_AdjNum=0 -> #NAME? | B2: =OpenSolver_AdjNum=1 -> #NAME?
A3: =OpenSolver_ChosenSolver=GLPK -> #NAME? | B3: =OpenSolver_ChosenSolver=Google -> #NAME?
A4: =OpenSolver_FastBuild=0 -> #NAME? | B4: =OpenSolver_FastBuild=0 -> #NAME?
A5: =OpenSolver_LinearityCheck=1 -> #NAME? | B5: =OpenSolver_LinearityCheck=1 -> #NAME?
A6: =solver_neg=1 -> #NAME? | B6: =solver_adj=Optimization!B41:Q56 -> #NAME?
A7: =solver_num=0 -> #NAME? | B7: =solver_lhs1=Optimization!R41:R56 -> #NAME?
A8: =solver_sho=1 -> #NAME? | B8: =solver_lhs2=Optimization!B57:Q57 -> #NAME?
A9: =solver_typ=2 -> #NAME? | B9: =solver_lhs3=Optimization!B41:Q56 -> #NAME?
A10: =solver_val=0 -> #NAME? | B10: =solver_lhs4=Optimization!B41:G46 -> #NAME?
B11: =solver_lhs5=Optimization!H47:L51 -> #NAME?
B12: =solver_lhs6=Optimization!M52:Q56 -> #NAME?
B13: =solver_neg=1 -> #NAME?
B14: =solver_num=6 -> #NAME?
B15: =solver_opt=Optimization!S23 -> #NAME?
B16: =solver_rel1=2 -> #NAME?
B17: =solver_rel2=2 -> #NAME?
B18: =solver_rel3=5 -> #NAME?
B19: =solver_rel4=2 -> #NAME?
B20: =solver_rel5=2 -> #NAME?
B21: =solver_rel6=2 -> #NAME?
B22: =solver_rhs1=Optimization!S41:S56 -> #NAME?
B23: =solver_rhs2=Optimization!B58:Q58 -> #NAME?
B24: =solver_rhs3=binary -> #NAME?
B25: =solver_rhs4=Optimization!B23:G28 -> #NAME?
B26: =solver_rhs5=Optimization!H29:L33 -> #NAME?
B27: =solver_rhs6=Optimization!M34:Q38 -> #NAME?
B28: =solver_sho=1 -> #NAME?
B29: =solver_typ=2 -> #NAME?
B30: =solver_val=0 -> #NAME?
